Workbook

Sheet COMBINED-CLEANED
A1: NASDAQ Composite Index (NASDAQCOM) | FRED | St. Louis Fed | B1: Inflation | C1: Unemployment | D1: Interest Rate | E1: GDP | F1: GDP Yearly Growth | G1: NASDAQ | H1: NASDAQ Yearly Growith
A2: 30317 | B2: =VLOOKUP(A2, INFLATION!$A$2:$B$514, 2, FALSE) -> 5.0146534 | C2: =VLOOKUP(A2, UNRATE!$A$2:$B$933, 2, FALSE) -> 10.4 | D2: =VLOOKUP(A2, FEDFUNDS!$A$2:$B$933, 2, FALSE) -> 8.68 | E2: =VLOOKUP(A2, GDP!$A$2:$B$933, 2, FALSE) -> 3473.413 | G2: =IFNA( IF(ISBLANK(VLOOKUP(A2, NASDAQCOM!$A$2:$B$14300, 2, FALSE)), NA(), VLOOKUP(A2, NASDAQCOM!$A$2:$B$14300, 2, FALSE)), IFNA( IF(ISBLANK(VLOOKUP(A2+1, NASDAQCOM!$A$2:$B$14300, 2, FALSE)), NA(), VLOOKUP(A2+1, NASDAQCOM!$A$2:$B$14300, 2, FALSE)), IFNA( IF(ISBLANK(VLOOKUP(A2+2, NASDAQCOM!$A$2:$B$14300, 2, FALSE)), NA(), VLOOKUP(A2+2, NASDAQCOM!$A$2:$B$14300, 2, FALSE)), IFNA( IF(ISBLANK(VLOOKUP(A2+3, NASDAQCOM!$A$2:$B$14300, 2, FALSE)), NA(), VLOOKUP(A2+3, NASDAQCOM!$A$2:$B$14300, 2, FALSE)), "No Valid Trading Day Found within 4 days" ) ) ) ) -> 230.59
A3: =EDATE(A2, 3) -> 30407 | B3: =VLOOKUP(A3, INFLATION!$A$2:$B$514, 2, FALSE) -> 4.8280542 | C3: =VLOOKUP(A3, UNRATE!$A$2:$B$933, 2, FALSE) -> 10.2 | D3: =VLOOKUP(A3, FEDFUNDS!$A$2:$B$933, 2, FALSE) -> 8.8 | E3: =VLOOKUP(A3, GDP!$A$2:$B$933, 2, FALSE) -> 3578.848 | G3: =IFNA( IF(ISBLANK(VLOOKUP(A3, NASDAQCOM!$A$2:$B$14300, 2, FALSE)), NA(), VLOOKUP(A3, NASDAQCOM!$A$2:$B$14300, 2, FALSE)), IFNA( IF(ISBLANK(VLOOKUP(A3+1, NASDAQCOM!$A$2:$B$14300, 2, FALSE)), NA(), VLOOKUP(A3+1, NASDAQCOM!$A$2:$B$14300, 2, FALSE)), IFNA( IF(ISBLANK(VLOOKUP(A3+2, NASDAQCOM!$A$2:$B$14300, 2, FALSE)), NA(), VLOOKUP(A3+2, NASDAQCOM!$A$2:$B$14300, 2, FALSE)), IFNA( IF(ISBLANK(VLOOKUP(A3+3, NASDAQCOM!$A$2:$B$14300, 2, FALSE)), NA(), VLOOKUP(A3+3, NASDAQCOM!$A$2:$B$14300, 2, FALSE)), "No Valid Trading Day Found within 4 days" ) ) ) ) -> 268.73
A4: =EDATE(A3, 3) -> 30498 | B4: =VLOOKUP(A4, INFLATION!$A$2:$B$514, 2, FALSE) -> 3.6975822 | C4: =VLOOKUP(A4, UNRATE!$A$2:$B$933, 2, FALSE) -> 9.4 | D4: =VLOOKUP(A4, FEDFUNDS!$A$2:$B$933, 2, FALSE) -> 9.37 | E4: =VLOOKUP(A4, GDP!$A$2:$B$933, 2, FALSE) -> 3689.179 | G4: =IFNA( IF(ISBLANK(VLOOKUP(A4, NASDAQCOM!$A$2:$B$14300, 2, FALSE)), NA(), VLOOKUP(A4, NASDAQCOM!$A$2:$B$14300, 2, FALSE)), IFNA( IF(ISBLANK(VLOOKUP(A4+1, NASDAQCOM!$A$2:$B$14300, 2, FALSE)), NA(), VLOOKUP(A4+1, NASDAQCOM!$A$2:$B$14300, 2, FALSE)), IFNA( IF(ISBLANK(VLOOKUP(A4+2, NASDAQCOM!$A$2:$B$14300, 2, FALSE)), NA(), VLOOKUP(A4+2, NASDAQCOM!$A$2:$B$14300, 2, FALSE)), IFNA( IF(ISBLANK(VLOOKUP(A4+3, NASDAQCOM!$A$2:$B$14300, 2, FALSE)), NA(), VLOOKUP(A4+3, NASDAQCOM!$A$2:$B$14300, 2, FALSE)), "No Valid Trading Day Found within 4 days" ) ) ) ) -> 321.58
A5: =EDATE(A4, 3) -> 30590 | B5: =VLOOKUP(A5, INFLATION!$A$2:$B$514, 2, FALSE) -> 4.7097067 | C5: =VLOOKUP(A5, UNRATE!$A$2:$B$933, 2, FALSE) -> 8.8 | D5: =VLOOKUP(A5, FEDFUNDS!$A$2:$B$933, 2, FALSE) -> 9.48 | E5: =VLOOKUP(A5, GDP!$A$2:$B$933, 2, FALSE) -> 3794.706 | G5: =IFNA( IF(ISBLANK(VLOOKUP(A5, NASDAQCOM!$A$2:$B$14300, 2, FALSE)), NA(), VLOOKUP(A5, NASDAQCOM!$A$2:$B$14300, 2, FALSE)), IFNA( IF(ISBLANK(VLOOKUP(A5+1, NASDAQCOM!$A$2:$B$14300, 2, FALSE)), NA(), VLOOKUP(A5+1, NASDAQCOM!$A$2:$B$14300, 2, FALSE)), IFNA( IF(ISBLANK(VLOOKUP(A5+2, NASDAQCOM!$A$2:$B$14300, 2, FALSE)), NA(), VLOOKUP(A5+2, NASDAQCOM!$A$2:$B$14300, 2, FALSE)), IFNA( IF(ISBLANK(VLOOKUP(A5+3, NASDAQCOM!$A$2:$B$14300, 2, FALSE)), NA(), VLOOKUP(A5+3, NASDAQCOM!$A$2:$B$14300, 2, FALSE)), "No Valid Trading Day Found within 4 days" ) ) ) ) -> 294.64
A6: =EDATE(A5, 3) -> 30682 | B6: =VLOOKUP(A6, INFLATION!$A$2:$B$514, 2, FALSE) -> 4.8524905 | C6: =VLOOKUP(A6, UNRATE!$A$2:$B$933, 2, FALSE) -> 8 | D6: =VLOOKUP(A6, FEDFUNDS!$A$2:$B$933, 2, FALSE) -> 9.56 | E6: =VLOOKUP(A6, GDP!$A$2:$B$933, 2, FALSE) -> 3908.054 | F6: =((E6-E2)/E2) * 100 -> 12.513369 | G6: =IFNA( IF(ISBLANK(VLOOKUP(A6, NASDAQCOM!$A$2:$B$14300, 2, FALSE)), NA(), VLOOKUP(A6, NASDAQCOM!$A$2:$B$14300, 2, FALSE)), IFNA( IF(ISBLANK(VLOOKUP(A6+1, NASDAQCOM!$A$2:$B$14300, 2, FALSE)), NA(), VLOOKUP(A6+1, NASDAQCOM!$A$2:$B$14300, 2, FALSE)), IFNA( IF(ISBLANK(VLOOKUP(A6+2, NASDAQCOM!$A$2:$B$14300, 2, FALSE)), NA(), VLOOKUP(A6+2, NASDAQCOM!$A$2:$B$14300, 2, FALSE)), IFNA( IF(ISBLANK(VLOOKUP(A6+3, NASDAQCOM!$A$2:$B$14300, 2, FALSE)), NA(), VLOOKUP(A6+3, NASDAQCOM!$A$2:$B$14300, 2, FALSE)), "No Valid Trading Day Found within 4 days" ) ) ) ) -> 277.63 | H6: =((G6-G2)/G2) * 100 -> 20.399844
A7: =EDATE(A6, 3) -> 30773 | B7: =VLOOKUP(A7, INFLATION!$A$2:$B$514, 2, FALSE) -> 4.4737538 | C7: =VLOOKUP(A7, UNRATE!$A$2:$B$933, 2, FALSE) -> 7.7 | D7: =VLOOKUP(A7, FEDFUNDS!$A$2:$B$933, 2, FALSE) -> 10.29 | E7: =VLOOKUP(A7, GDP!$A$2:$B$933, 2, FALSE) -> 4009.601 | F7: =((E7-E3)/E3) * 100 -> 12.03608 | G7: =IFNA( IF(ISBLANK(VLOOKUP(A7, NASDAQCOM!$A$2:$B$14300, 2, FALSE)), NA(), VLOOKUP(A7, NASDAQCOM!$A$2:$B$14300, 2, FALSE)), IFNA( IF(ISBLANK(VLOOKUP(A7+1, NASDAQCOM!$A$2:$B$14300, 2, FALSE)), NA(), VLOOKUP(A7+1, NASDAQCOM!$A$2:$B$14300, 2, FALSE)), IFNA( IF(ISBLANK(VLOOKUP(A7+2, NASDAQCOM!$A$2:$B$14300, 2, FALSE)), NA(), VLOOKUP(A7+2, NASDAQCOM!$A$2:$B$14300, 2, FALSE)), IFNA( IF(ISBLANK(VLOOKUP(A7+3, NASDAQCOM!$A$2:$B$14300, 2, FALSE)), NA(), VLOOKUP(A7+3, NASDAQCOM!$A$2:$B$14300, 2, FALSE)), "No Valid Trading Day Found within 4 days" ) ) ) ) -> 249.8 | H7: =((G7-G3)/G3) * 100 -> -7.0442452
A8: =EDATE(A7, 3) -> 30864 | B8: =VLOOKUP(A8, INFLATION!$A$2:$B$514, 2, FALSE) -> 4.7097067 | C8: =VLOOKUP(A8, UNRATE!$A$2:$B$933, 2, FALSE) -> 7.5 | D8: =VLOOKUP(A8, FEDFUNDS!$A$2:$B$933, 2, FALSE) -> 11.23 | E8: =VLOOKUP(A8, GDP!$A$2:$B$933, 2, FALSE) -> 4084.25 | F8: =((E8-E4)/E4) * 100 -> 10.708914 | G8: =IFNA( IF(ISBLANK(VLOOKUP(A8, NASDAQCOM!$A$2:$B$14300, 2, FALSE)), NA(), VLOOKUP(A8, NASDAQCOM!$A$2:$B$14300, 2, FALSE)), IFNA( IF(ISBLANK(VLOOKUP(A8+1, NASDAQCOM!$A$2:$B$14300, 2, FALSE)), NA(), VLOOKUP(A8+1, NASDAQCOM!$A$2:$B$14300, 2, FALSE)), IFNA( IF(ISBLANK(VLOOKUP(A8+2, NASDAQCOM!$A$2:$B$14300, 2, FALSE)), NA(), VLOOKUP(A8+2, NASDAQCOM!$A$2:$B$14300, 2, FALSE)), IFNA( IF(ISBLANK(VLOOKUP(A8+3, NASDAQCOM!$A$2:$B$14300, 2, FALSE)), NA(), VLOOKUP(A8+3, NASDAQCOM!$A$2:$B$14300, 2, FALSE)), "No Valid Trading Day Found within 4 days" ) ) ) ) -> 237.91 | H8: =((G8-G4)/G4) * 100 -> -26.018409
A9: =EDATE(A8, 3) -> 30956 | B9: =VLOOKUP(A9, INFLATION!$A$2:$B$514, 2, FALSE) -> 3.4965341 | C9: =VLOOKUP(A9, UNRATE!$A$2:$B$933, 2, FALSE) -> 7.4 | D9: =VLOOKUP(A9, FEDFUNDS!$A$2:$B$933, 2, FALSE) -> 9.99 | E9: =VLOOKUP(A9, GDP!$A$2:$B$933, 2, FALSE) -> 4148.551 | F9: =((E9-E5)/E5) * 100 -> 9.3247013 | G9: =IFNA( IF(ISBLANK(VLOOKUP(A9, NASDAQCOM!$A$2:$B$14300, 2, FALSE)), NA(), VLOOKUP(A9, NASDAQCOM!$A$2:$B$14300, 2, FALSE)), IFNA( IF(ISBLANK(VLOOKUP(A9+1, NASDAQCOM!$A$2:$B$14300, 2, FALSE)), NA(), VLOOKUP(A9+1, NASDAQCOM!$A$2:$B$14300, 2, FALSE)), IFNA( IF(ISBLANK(VLOOKUP(A9+2, NASDAQCOM!$A$2:$B$14300, 2, FALSE)), NA(), VLOOKUP(A9+2, NASDAQCOM!$A$2:$B$14300, 2, FALSE)), IFNA( IF(ISBLANK(VLOOKUP(A9+3, NASDAQCOM!$A$2:$B$14300, 2, FALSE)), NA(), VLOOKUP(A9+3, NASDAQCOM!$A$2:$B$14300, 2, FALSE)), "No Valid Trading Day Found within 4 days" ) ) ) ) -> 247.86 | H9: =((G9-G5)/G5) * 100 -> -15.877002
A10: =EDATE(A9, 3) -> 31048 | B10: =VLOOKUP(A10, INFLATION!$A$2:$B$514, 2, FALSE) -> 3.0749027 | C10: =VLOOKUP(A10, UNRATE!$A$2:$B$933, 2, FALSE) -> 7.3 | D10: =VLOOKUP(A10, FEDFUNDS!$A$2:$B$933, 2, FALSE) -> 8.35 | E10: =VLOOKUP(A10, GDP!$A$2:$B$933, 2, FALSE) -> 4230.168 | F10: =((E10-E6)/E6) * 100 -> 8.2423119 | G10: =IFNA( IF(ISBLANK(VLOOKUP(A10, NASDAQCOM!$A$2:$B$14300, 2, FALSE)), NA(), VLOOKUP(A10, NASDAQCOM!$A$2:$B$14300, 2, FALSE)), IFNA( IF(ISBLANK(VLOOKUP(A10+1, NASDAQCOM!$A$2:$B$14300, 2, FALSE)), NA(), VLOOKUP(A10+1, NASDAQCOM!$A$2:$B$14300, 2, FALSE)), IFNA( IF(ISBLANK(VLOOKUP(A10+2, NASDAQCOM!$A$2:$B$14300, 2, FALSE)), NA(), VLOOKUP(A10+2, NASDAQCOM!$A$2:$B$14300, 2, FALSE)), IFNA( IF(ISBLANK(VLOOKUP(A10+3, NASDAQCOM!$A$2:$B$14300, 2, FALSE)), NA(), VLOOKUP(A10+3, NASDAQCOM!$A$2:$B$14300, 2, FALSE)), "No Valid Trading Day Found within 4 days" ) ) ) ) -> 245.91 | H10: =((G10-G6)/G6) * 100 -> -11.425278
A11: =EDATE(A10, 3) -> 31138 | B11: =VLOOKUP(A11, INFLATION!$A$2:$B$514, 2, FALSE) -> 4.4936163 | C11: =VLOOKUP(A11, UNRATE!$A$2:$B$933, 2, FALSE) -> 7.3 | D11: =VLOOKUP(A11, FEDFUNDS!$A$2:$B$933, 2, FALSE) -> 8.27 | E11: =VLOOKUP(A11, GDP!$A$2:$B$933, 2, FALSE) -> 4294.887 | F11: =((E11-E7)/E7) * 100 -> 7.115072 | G11: =IFNA( IF(ISBLANK(VLOOKUP(A11, NASDAQCOM!$A$2:$B$14300, 2, FALSE)), NA(), VLOOKUP(A11, NASDAQCOM!$A$2:$B$14300, 2, FALSE)), IFNA( IF(ISBLANK(VLOOKUP(A11+1, NASDAQCOM!$A$2:$B$14300, 2, FALSE)), NA(), VLOOKUP(A11+1, NASDAQCOM!$A$2:$B$14300, 2, FALSE)), IFNA( IF(ISBLANK(VLOOKUP(A11+2, NASDAQCOM!$A$2:$B$14300, 2, FALSE)), NA(), VLOOKUP(A11+2, NASDAQCOM!$A$2:$B$14300, 2, FALSE)), IFNA( IF(ISBLANK(VLOOKUP(A11+3, NASDAQCOM!$A$2:$B$14300, 2, FALSE)), NA(), VLOOKUP(A11+3, NASDAQCOM!$A$2:$B$14300, 2, FALSE)), "No Valid Trading Day Found within 4 days" ) ) ) ) -> 280.32 | H11: =((G11-G7)/G7) * 100 -> 12.217774
A12: =EDATE(A11, 3) -> 31229 | B12: =VLOOKUP(A12, INFLATION!$A$2:$B$514, 2, FALSE) -> 2.4314834 | C12: =VLOOKUP(A12, UNRATE!$A$2:$B$933, 2, FALSE) -> 7.4 | D12: =VLOOKUP(A12, FEDFUNDS!$A$2:$B$933, 2, FALSE) -> 7.88 | E12: =VLOOKUP(A12, GDP!$A$2:$B$933, 2, FALSE) -> 4386.773 | F12: =((E12-E8)/E8) * 100 -> 7.4070637 | G12: =IFNA( IF(ISBLANK(VLOOKUP(A12, NASDAQCOM!$A$2:$B$14300, 2, FALSE)), NA(), VLOOKUP(A12, NASDAQCOM!$A$2:$B$14300, 2, FALSE)), IFNA( IF(ISBLANK(VLOOKUP(A12+1, NASDAQCOM!$A$2:$B$14300, 2, FALSE)), NA(), VLOOKUP(A12+1, NASDAQCOM!$A$2:$B$14300, 2, FALSE)), IFNA( IF(ISBLANK(VLOOKUP(A12+2, NASDAQCOM!$A$2:$B$14300, 2, FALSE)), NA(), VLOOKUP(A12+2, NASDAQCOM!$A$2:$B$14300, 2, FALSE)), IFNA( IF(ISBLANK(VLOOKUP(A12+3, NASDAQCOM!$A$2:$B$14300, 2, FALSE)), NA(), VLOOKUP(A12+3, NASDAQCOM!$A$2:$B$14300, 2, FALSE)), "No Valid Trading Day Found within 4 days" ) ) ) ) -> 296.48 | H12: =((G12-G8)/G8) * 100 -> 24.618553
A13: =EDATE(A12, 3) -> 31321 | B13: =VLOOKUP(A13, INFLATION!$A$2:$B$514, 2, FALSE) -> 3.4628545 | C13: =VLOOKUP(A13, UNRATE!$A$2:$B$933, 2, FALSE) -> 7.1 | D13: =VLOOKUP(A13, FEDFUNDS!$A$2:$B$933, 2, FALSE) -> 7.99 | E13: =VLOOKUP(A13, GDP!$A$2:$B$933, 2, FALSE) -> 4444.094 | F13: =((E13-E9)/E9) * 100 -> 7.1240055 | G13: =IFNA( IF(ISBLANK(VLOOKUP(A13, NASDAQCOM!$A$2:$B$14300, 2, FALSE)), NA(), VLOOKUP(A13, NASDAQCOM!$A$2:$B$14300, 2, FALSE)), IFNA( IF(ISBLANK(VLOOKUP(A13+1, NASDAQCOM!$A$2:$B$14300, 2, FALSE)), NA(), VLOOKUP(A13+1, NASDAQCOM!$A$2:$B$14300, 2, FALSE)), IFNA( IF(ISBLANK(VLOOKUP(A13+2, NASDAQCOM!$A$2:$B$14300, 2, FALSE)), NA(), VLOOKUP(A13+2, NASDAQCOM!$A$2:$B$14300, 2, FALSE)), IFNA( IF(ISBLANK(VLOOKUP(A13+3, NASDAQCOM!$A$2:$B$14300, 2, FALSE)), NA(), VLOOKUP(A13+3, NASDAQCOM!$A$2:$B$14300, 2, FALSE)), "No Valid Trading Day Found within 4 days" ) ) ) ) -> 281.77 | H13: =((G13-G9)/G9) * 100 -> 13.68111
A14: =EDATE(A13, 3) -> 31413 | B14: =VLOOKUP(A14, INFLATION!$A$2:$B$514, 2, FALSE) -> 4.4233004 | C14: =VLOOKUP(A14, UNRATE!$A$2:$B$933, 2, FALSE) -> 6.7 | D14: =VLOOKUP(A14, FEDFUNDS!$A$2:$B$933, 2, FALSE) -> 8.14 | E14: =VLOOKUP(A14, GDP!$A$2:$B$933, 2, FALSE) -> 4507.894 | F14: =((E14-E10)/E10) * 100 -> 6.5653657 | G14: =IFNA( IF(ISBLANK(VLOOKUP(A14, NASDAQCOM!$A$2:$B$14300, 2, FALSE)), NA(), VLOOKUP(A14, NASDAQCOM!$A$2:$B$14300, 2, FALSE)), IFNA( IF(ISBLANK(VLOOKUP(A14+1, NASDAQCOM!$A$2:$B$14300, 2, FALSE)), NA(), VLOOKUP(A14+1, NASDAQCOM!$A$2:$B$14300, 2, FALSE)), IFNA( IF(ISBLANK(VLOOKUP(A14+2, NASDAQCOM!$A$2:$B$14300, 2, FALSE)), NA(), VLOOKUP(A14+2, NASDAQCOM!$A$2:$B$14300, 2, FALSE)), IFNA( IF(ISBLANK(VLOOKUP(A14+3, NASDAQCOM!$A$2:$B$14300, 2, FALSE)), NA(), VLOOKUP(A14+3, NASDAQCOM!$A$2:$B$14300, 2, FALSE)), "No Valid Trading Day Found within 4 days" ) ) ) ) -> 324.99 | H14: =((G14-G10)/G10) * 100 -> 32.158107
A15: =EDATE(A14, 3) -> 31503 | B15: =VLOOKUP(A15, INFLATION!$A$2:$B$514, 2, FALSE) -> 4.1696244 | C15: =VLOOKUP(A15, UNRATE!$A$2:$B$933, 2, FALSE) -> 7.1 | D15: =VLOOKUP(A15, FEDFUNDS!$A$2:$B$933, 2, FALSE) -> 6.99 | E15: =VLOOKUP(A15, GDP!$A$2:$B$933, 2, FALSE) -> 4545.34 | F15: =((E15-E11)/E11) * 100 -> 5.8314223 | G15: =IFNA( IF(ISBLANK(VLOOKUP(A15, NASDAQCOM!$A$2:$B$14300, 2, FALSE)), NA(), VLOOKUP(A15, NASDAQCOM!$A$2:$B$14300, 2, FALSE)), IFNA( IF(ISBLANK(VLOOKUP(A15+1, NASDAQCOM!$A$2:$B$14300, 2, FALSE)), NA(), VLOOKUP(A15+1, NASDAQCOM!$A$2:$B$14300, 2, FALSE)), IFNA( IF(ISBLANK(VLOOKUP(A15+2, NASDAQCOM!$A$2:$B$14300, 2, FALSE)), NA(), VLOOKUP(A15+2, NASDAQCOM!$A$2:$B$14300, 2, FALSE)), IFNA( IF(ISBLANK(VLOOKUP(A15+3, NASDAQCOM!$A$2:$B$14300, 2, FALSE)), NA(), VLOOKUP(A15+3, NASDAQCOM!$A$2:$B$14300, 2, FALSE)), "No Valid Trading Day Found within 4 days" ) ) ) ) -> 374.15 | H15: =((G15-G11)/G11) * 100 -> 33.47246
A16: =EDATE(A15, 3) -> 31594 | B16: =VLOOKUP(A16, INFLATION!$A$2:$B$514, 2, FALSE) -> 4.0196063 | C16: =VLOOKUP(A16, UNRATE!$A$2:$B$933, 2, FALSE) -> 7 | D16: =VLOOKUP(A16, FEDFUNDS!$A$2:$B$933, 2, FALSE) -> 6.56 | E16: =VLOOKUP(A16, GDP!$A$2:$B$933, 2, FALSE) -> 4607.669 | F16: =((E16-E12)/E12) * 100 -> 5.035501 | G16: =IFNA( IF(ISBLANK(VLOOKUP(A16, NASDAQCOM!$A$2:$B$14300, 2, FALSE)), NA(), VLOOKUP(A16, NASDAQCOM!$A$2:$B$14300, 2, FALSE)), IFNA( IF(ISBLANK(VLOOKUP(A16+1, NASDAQCOM!$A$2:$B$14300, 2, FALSE)), NA(), VLOOKUP(A16+1, NASDAQCOM!$A$2:$B$14300, 2, FALSE)), IFNA( IF(ISBLANK(VLOOKUP(A16+2, NASDAQCOM!$A$2:$B$14300, 2, FALSE)), NA(), VLOOKUP(A16+2, NASDAQCOM!$A$2:$B$14300, 2, FALSE)), IFNA( IF(ISBLANK(VLOOKUP(A16+3, NASDAQCOM!$A$2:$B$14300, 2, FALSE)), NA(), VLOOKUP(A16+3, NASDAQCOM!$A$2:$B$14300, 2, FALSE)), "No Valid Trading Day Found within 4 days" ) ) ) ) -> 407.61 | H16: =((G16-G12)/G12) * 100 -> 37.483135
A17: =EDATE(A16, 3) -> 31686 | B17: =VLOOKUP(A17, INFLATION!$A$2:$B$514, 2, FALSE) -> 4.170621 | C17: =VLOOKUP(A17, UNRATE!$A$2:$B$933, 2, FALSE) -> 7 | D17: =VLOOKUP(A17, FEDFUNDS!$A$2:$B$933, 2, FALSE) -> 5.85 | E17: =VLOOKUP(A17, GDP!$A$2:$B$933, 2, FALSE) -> 4657.627 | F17: =((E17-E13)/E13) * 100 -> 4.8048714 | G17: =IFNA( IF(ISBLANK(VLOOKUP(A17, NASDAQCOM!$A$2:$B$14300, 2, FALSE)), NA(), VLOOKUP(A17, NASDAQCOM!$A$2:$B$14300, 2, FALSE)), IFNA( IF(ISBLANK(VLOOKUP(A17+1, NASDAQCOM!$A$2:$B$14300, 2, FALSE)), NA(), VLOOKUP(A17+1, NASDAQCOM!$A$2:$B$14300, 2, FALSE)), IFNA( IF(ISBLANK(VLOOKUP(A17+2, NASDAQCOM!$A$2:$B$14300, 2, FALSE)), NA(), VLOOKUP(A17+2, NASDAQCOM!$A$2:$B$14300, 2, FALSE)), IFNA( IF(ISBLANK(VLOOKUP(A17+3, NASDAQCOM!$A$2:$B$14300, 2, FALSE)), NA(), VLOOKUP(A17+3, NASDAQCOM!$A$2:$B$14300, 2, FALSE)), "No Valid Trading Day Found within 4 days" ) ) ) ) -> 352.34 | H17: =((G17-G13)/G13) * 100 -> 25.04525
... A172: =EDATE(A171, 3) -> 45839 | B172: =VLOOKUP(A172, INFLATION!$A$2:$B$514, 2, FALSE) -> 3.3679448 | C172: =VLOOKUP(A172, UNRATE!$A$2:$B$933, 2, FALSE) -> 4.2 | D172: =VLOOKUP(A172, FEDFUNDS!$A$2:$B$933, 2, FALSE) -> 4.33 | E172: =VLOOKUP(A172, GDP!$A$2:$B$933, 2, FALSE) -> #N/A | F172: =((E172-E168)/E168) * 100 -> #N/A | G172: =IFNA( IF(ISBLANK(VLOOKUP(A172, NASDAQCOM!$A$2:$B$14300, 2, FALSE)), NA(), VLOOKUP(A172, NASDAQCOM!$A$2:$B$14300, 2, FALSE)), IFNA( IF(ISBLANK(VLOOKUP(A172+1, NASDAQCOM!$A$2:$B$14300, 2, FALSE)), NA(), VLOOKUP(A172+1, NASDAQCOM!$A$2:$B$14300, 2, FALSE)), IFNA( IF(ISBLANK(VLOOKUP(A172+2, NASDAQCOM!$A$2:$B$14300, 2, FALSE)), NA(), VLOOKUP(A172+2, NASDAQCOM!$A$2:$B$14300, 2, FALSE)), IFNA( IF(ISBLANK(VLOOKUP(A172+3, NASDAQCOM!$A$2:$B$14300, 2, FALSE)), NA(), VLOOKUP(A172+3, NASDAQCOM!$A$2:$B$14300, 2, FALSE)), "No Valid Trading Day Found within 4 days" ) ) ) ) -> 20202.89 | H172: =((G172-G168)/G168) * 100 -> 12.995979
A173: =EDATE(A172, 3) -> 45931 | B173: =VLOOKUP(A173, INFLATION!$A$2:$B$514, 2, FALSE) -> #N/A | C173: =VLOOKUP(A173, UNRATE!$A$2:$B$933, 2, FALSE) -> #N/A

Sheet NASDAQCOM
A1: observation_date | B1: NASDAQCOM
A2: 25969 | B2: 100
A3: 25972 | B3: 100.84
A4: 25973 | B4: 100.76
A5: 25974 | B5: 100.69
A6: 25975 | B6: 101.45
A7: 25976 | B7: 102.05
A8: 25979
A9: 25980 | B9: 102.19
A10: 25981 | B10: 101.74
A11: 25982 | B11: 101.42
A12: 25983 | B12: 100.7
A13: 25986 | B13: 99.68
A14: 25987 | B14: 99.72
A15: 25988 | B15: 100.64
A16: 25989 | B16: 101.23
A17: 25990 | B17: 101.34
A18: 25993 | B18: 101.78
A19: 25994 | B19: 101.84
A20: 25995 | B20: 102.07
... A46: 26031 | B46: 108.38
A47: 26032
A48: 26035 | B48: 108.87
A49: 26036 | B49: 108.85
A50: 26037 | B50: 109.08
A51: 26038 | B51: 109.69
A52: 26039 | B52: 109.96
A53: 26042 | B53: 110.16
A54: 26043 | B54: 109.53
A55: 26044 | B55: 109.52
A56: 26045 | B56: 109.99
A57: 26046 | B57: 110.69
A58: 26049 | B58: 111.13
A59: 26050 | B59: 111.69
... A82: 26081 | B82: 108.25
A83: 26084
A84: 26085 | B84: 108.87
A85: 26086 | B85: 109.56
A86: 26087 | B86: 110.22
A87: 26088 | B87: 110.66
...

Sheet FEDFUNDS
A1: observation_date | B1: FEDFUNDS
A2: 19943 | B2: 0.8
A3: 19937 | B3: 1.22
A4: 19968 | B4: 1.07
A5: 19998 | B5: 0.85
A6: 20029 | B6: 0.83
A7: 20059 | B7: 1.28
A8: 20090 | B8: 1.39
A9: 20121 | B9: 1.29
A10: 20149 | B10: 1.35
A11: 20180 | B11: 1.43
A12: 20210 | B12: 1.43
A13: 20241 | B13: 1.64
... A857: 45931 | B857: 4.09

Sheet GDP
A1: observation_date | B1: GDP
A2: 17168 | B2: 243.164
A3: 17258 | B3: 245.968
A4: 17349 | B4: 249.585
A5: 17441 | B5: 259.745
A6: 17533 | B6: 265.742
A7: 17624 | B7: 272.567
A8: 17715 | B8: 279.196
A9: 17807 | B9: 280.366
A10: 17899 | B10: 275.034
A11: 17989 | B11: 271.351
A12: 18080 | B12: 272.889
A13: 18172 | B13: 270.627
... A315: 45748 | B315: 30485.729

Sheet UNRATE
A1: observation_date | B1: UNRATE
A2: 17533 | B2: 3.4
A3: 17564 | B3: 3.8
A4: 17593 | B4: 4
A5: 17624 | B5: 3.9
A6: 17654 | B6: 3.5
A7: 17685 | B7: 3.6
A8: 17715 | B8: 3.6
A9: 17746 | B9: 3.9
A10: 17777 | B10: 3.8
A11: 17807 | B11: 3.7
A12: 17838 | B12: 3.8
A13: 17868 | B13: 4
... A933: 45870 | B933: 4.3

Sheet INFLATION
A1: observation_date | B1: MEDCPIM158SFRBCLE
A2: 30317 | B2: 5.0146534
A3: 30348 | B3: 4.9525451
A4: 30376 | B4: 3.6122606
A5: 30407 | B5: 4.8280542
A6: 30437 | B6: 3.7673263
A7: 30468 | B7: 2.4412978
A8: 30498 | B8: 3.6975822
A9: 30529 | B9: 4.8969904
A10: 30560 | B10: 4.8378279
A11: 30590 | B11: 4.7097067
A12: 30621 | B12: 4.8820717
A13: 30651 | B13: 3.6267657
... A514: 45901 | B514: 2.384737

Sheet Sheet1
B1: 30317 | C1: 30407 | D1: =EDATE(C1, 3) -> 30498 | E1: =EDATE(D1, 3) -> 30590 | F1: =EDATE(E1, 3) -> 30682 | G1: =EDATE(F1, 3) -> 30773 | H1: =EDATE(G1, 3) -> 30864 | I1: =EDATE(H1, 3) -> 30956 | J1: =EDATE(I1, 3) -> 31048 | K1: =EDATE(J1, 3) -> 31138 | ... AA1: =EDATE(Z1, 3) -> 32599
A2: Inflation
A3: Unemployment
A4: Interest Rate
A5: GDP
A6: GDP Yearly Growth
A7: NASDAQ
A8: NASDAQ Yearly Growith
